Workbook

Sheet Sheet
A1: Libro | B1: Clase | C1: Nivel | D1: Código Cuenta Contable | E1: Cuenta Contable | F1: Naturaleza Saldo Anterior | G1: Saldo Anterior | H1: Valor Débito | I1: Valor Crédito | J1: Naturaleza Nuevo Saldo | K1: Nuevo Saldo
A2: NIIF FISCAL | B2: ACTIVO | C2: 1 | D2: 1 | E2: ACTIVO | F2: Debito | G2: 5.7681062e+10 | H2: 1.6970735e+10 | I2: 2.1890677e+10 | J2: Debito | K2: 5.276112e+10
A3: NIIF FISCAL | B3: ACTIVO | C3: 2 | D3: 11 | E3: EFECTIVO Y EQUIVALENTES AL EFECTIVO | F3: Debito | G3: 1.1217641e+08 | H3: 8.0179844e+09 | I3: 7.9675878e+09 | J3: Debito | K3: 1.62573e+08
A4: NIIF FISCAL | B4: ACTIVO | C4: 3 | D4: 1105 | E4: EFECTIVO | F4: Debito | G4: 27769010 | H4: 67108630 | I4: 70989026 | J4: Debito | K4: 23888614
A5: NIIF FISCAL | B5: ACTIVO | C5: 4 | D5: 110505 | E5: EFECTIVO | F5: Debito | G5: 27769010 | H5: 67108630 | I5: 70989026 | J5: Debito | K5: 23888614
A6: NIIF FISCAL | B6: ACTIVO | C6: 5 | D6: 11050505 | E6: CAJA GENERAL | F6: Debito | G6: 24969010 | H6: 64184326 | I6: 68064722 | J6: Debito | K6: 21088614
A7: NIIF FISCAL | B7: ACTIVO | C7: 6 | D7: 1105050505 | E7: CAJA PRINCIPAL | F7: Debito | G7: 22369010 | H7: 30453311 | I7: 34619008 | J7: Debito | K7: 18203313
A8: NIIF FISCAL | B8: ACTIVO | C8: 6 | D8: 1105050510 | E8: CAJA TESORERIA | F8: Debito | G8: 2000000 | H8: 2924304 | I8: 2924304 | J8: Debito | K8: 2000000
A9: NIIF FISCAL | B9: ACTIVO | C9: 6 | D9: 1105050515 | E9: CAJA URGENCIAS | F9: Debito | G9: 150000 | H9: 7763304.9 | I9: 7736204.1 | J9: Debito | K9: 177100.84
A10: NIIF FISCAL | B10: ACTIVO | C10: 6 | D10: 1105050520 | E10: CAJA CONSULTORIOS | F10: Debito | G10: 150000 | H10: 6253869 | I10: 6047869 | J10: Debito | K10: 356000
A11: NIIF FISCAL | B11: ACTIVO | C11: 6 | D11: 1105050525 | E11: CAJA FACTURACION | F11: Debito | G11: 200000 | H11: 16789537 | I11: 16737337 | J11: Debito | K11: 252200
A12: NIIF FISCAL | B12: ACTIVO | C12: 6 | D12: 1105050530 | E12: CAJA SEDE QUIROGA | F12: Debito | G12: 100000 | H12: 0 | I12: 0 | J12: Debito | K12: 100000
A13: NIIF FISCAL | B13: ACTIVO | C13: 5 | D13: 11050510 | E13: CAJA MENOR | F13: Debito | G13: 2800000 | H13: 2924304 | I13: 2924304 | J13: Debito | K13: 2800000
... A1650: NIIF FISCAL | B1650: COSTOS DE VENTAS Y OPERACION | C1650: 6 | D1650: 6135037115 | E1650: TRANSPORTE, PEAJES | F1650: Debito | G1650: 27900 | H1650: 0 | I1650: 0 | J1650: Debito | K1650: 27900

Sheet Bg
A1: Libro | B1: Clase | C1: Nivel | D1: Código Cuenta Contable | E1: Cuenta Contable | F1: Naturaleza Saldo Anterior | G1: Saldo Anterior | H1: Valor Débito | I1: Valor Crédito | J1: Naturaleza Nuevo Saldo | K1: Nuevo Saldo
A2: NIIF FISCAL | B2: ACTIVO | C2: 1 | D2: 1 | E2: ACTIVO | F2: Debito | G2: 5.7681062e+10 | H2: 1.6970735e+10 | I2: 2.1890677e+10 | J2: Debito | K2: 5.276112e+10
A3: NIIF FISCAL | B3: ACTIVO | C3: 2 | D3: 11 | E3: EFECTIVO Y EQUIVALENTES AL EFECTIVO | F3: Debito | G3: 1.1217641e+08 | H3: 8.0179844e+09 | I3: 7.9675878e+09 | J3: Debito | K3: 1.62573e+08
A4: NIIF FISCAL | B4: ACTIVO | C4: 3 | D4: 1105 | E4: EFECTIVO | F4: Debito | G4: 27769010 | H4: 67108630 | I4: 70989026 | J4: Debito | K4: 23888614
A5: NIIF FISCAL | B5: ACTIVO | C5: 4 | D5: 110505 | E5: EFECTIVO | F5: Debito | G5: 27769010 | H5: 67108630 | I5: 70989026 | J5: Debito | K5: 23888614
A6: NIIF FISCAL | B6: ACTIVO | C6: 5 | D6: 11050505 | E6: CAJA GENERAL | F6: Debito | G6: 24969010 | H6: 64184326 | I6: 68064722 | J6: Debito | K6: 21088614
A7: NIIF FISCAL | B7: ACTIVO | C7: 6 | D7: 1105050505 | E7: CAJA PRINCIPAL | F7: Debito | G7: 22369010 | H7: 30453311 | I7: 34619008 | J7: Debito | K7: 18203313
A8: NIIF FISCAL | B8: ACTIVO | C8: 6 | D8: 1105050510 | E8: CAJA TESORERIA | F8: Debito | G8: 2000000 | H8: 2924304 | I8: 2924304 | J8: Debito | K8: 2000000
A9: NIIF FISCAL | B9: ACTIVO | C9: 6 | D9: 1105050515 | E9: CAJA URGENCIAS | F9: Debito | G9: 150000 | H9: 7763304.9 | I9: 7736204.1 | J9: Debito | K9: 177100.84
A10: NIIF FISCAL | B10: ACTIVO | C10: 6 | D10: 1105050520 | E10: CAJA CONSULTORIOS | F10: Debito | G10: 150000 | H10: 6253869 | I10: 6047869 | J10: Debito | K10: 356000
A11: NIIF FISCAL | B11: ACTIVO | C11: 6 | D11: 1105050525 | E11: CAJA FACTURACION | F11: Debito | G11: 200000 | H11: 16789537 | I11: 16737337 | J11: Debito | K11: 252200
A12: NIIF FISCAL | B12: ACTIVO | C12: 6 | D12: 1105050530 | E12: CAJA SEDE QUIROGA | F12: Debito | G12: 100000 | H12: 0 | I12: 0 | J12: Debito | K12: 100000
A13: NIIF FISCAL | B13: ACTIVO | C13: 5 | D13: 11050510 | E13: CAJA MENOR | F13: Debito | G13: 2800000 | H13: 2924304 | I13: 2924304 | J13: Debito | K13: 2800000
... A1650: NIIF FISCAL | B1650: COSTOS DE VENTAS Y OPERACION | C1650: 6 | D1650: 6135037115 | E1650: TRANSPORTE, PEAJES | F1650: Debito | G1650: 27900 | H1650: 0 | I1650: 0 | J1650: Debito | K1650: 27900

Sheet Inventario
A1: Almacen Código | B1: Almacen Nombre | C1: Grupo Código | D1: Grupo Nombre | E1: Producto Código | F1: Producto Nombre | G1: Lote | H1: Fecha Vencimiento | I1: Unidad de Medida Código | J1: Unidad de Medida Nombre | K1: Concentración | L1: Cantidad | M1: Costo Unitario | N1: Costo Total
A2: 005 | B2: ALMACEN MEDICAMENTOS | C2: 001 | D2: MEDICAMENTOS | E2: 20058380-01 | F2: ADENOSINA 6 mg/2 ml Solución Inyectable | K2: 6 mg / 2 ml | L2: -10 | M2: 17324.683 | N2: -173246.83
A3: 008 | B3: ALMACEN GENERAL | C3: 015 | D3: MATERIALES Y REPUESTOS | E3: AM000228 | F3: VAPROX HC 15*3 PEROXIDO 59% REFPB011 | I3: 006 | J3: Unidad | L3: 1 | M3: -2924063 | N3: -2924063
A4: 010 | B4: STOCK TERAPIA URGENCIAS | C4: 002 | D4: MATERIAL MEDICO QUIRURGICO | E4: XT000085 | F4: SISTEMA SUCCION ADAPTADOR #14 TRAQUEAL CERRADA CORTA REF 0291 | I4: 006 | J4: Unidad | L4: 1 | M4: -133257.26 | N4: -133257.26
A5: 018 | B5: STOCK FISIOTERAPIA UCI 1 | C5: 002 | D5: MATERIAL MEDICO QUIRURGICO | E5: XT000085 | F5: SISTEMA SUCCION ADAPTADOR #14 TRAQUEAL CERRADA CORTA REF 0291 | I5: 006 | J5: Unidad | L5: 1 | M5: -133257.26 | N5: -133257.26
A6: 020 | B6: STOCK FISIOTERAPIA UCI 2 | C6: 002 | D6: MATERIAL MEDICO QUIRURGICO | E6: XT000085 | F6: SISTEMA SUCCION ADAPTADOR #14 TRAQUEAL CERRADA CORTA REF 0291 | I6: 006 | J6: Unidad | L6: 1 | M6: -133257.26 | N6: -133257.26
A7: 010 | B7: STOCK TERAPIA URGENCIAS | C7: 002 | D7: MATERIAL MEDICO QUIRURGICO | E7: XT000028 | F7: SISTEMA SUCCION ADAPTADOR #14 TRAQUEAL CERRADA LARGA | I7: 006 | J7: Unidad | L7: 1 | M7: -123798.43 | N7: -123798.43
A8: 018 | B8: STOCK FISIOTERAPIA UCI 1 | C8: 002 | D8: MATERIAL MEDICO QUIRURGICO | E8: XT000028 | F8: SISTEMA SUCCION ADAPTADOR #14 TRAQUEAL CERRADA LARGA | I8: 006 | J8: Unidad | L8: 1 | M8: -123798.43 | N8: -123798.43
A9: 020 | B9: STOCK FISIOTERAPIA UCI 2 | C9: 002 | D9: MATERIAL MEDICO QUIRURGICO | E9: XT000028 | F9: SISTEMA SUCCION ADAPTADOR #14 TRAQUEAL CERRADA LARGA | I9: 006 | J9: Unidad | L9: 1 | M9: -123798.43 | N9: -123798.43
A10: 018 | B10: STOCK FISIOTERAPIA UCI 1 | C10: 002 | D10: MATERIAL MEDICO QUIRURGICO | E10: XT000017 | F10: GUIA PARA INTUBACION X1 ESTILETE TUBO ENDOTRAQUE | I10: 006 | J10: Unidad | L10: 1 | M10: -58082.704 | N10: -58082.704
A11: 020 | B11: STOCK FISIOTERAPIA UCI 2 | C11: 002 | D11: MATERIAL MEDICO QUIRURGICO | E11: XT000017 | F11: GUIA PARA INTUBACION X1 ESTILETE TUBO ENDOTRAQUE | I11: 006 | J11: Unidad | L11: 1 | M11: -58082.704 | N11: -58082.704
A12: 052 | B12: CONSIGNACION LM INSTRUMENS S.A | C12: 002 | D12: MATERIAL MEDICO QUIRURGICO | E12: XT000090 | F12: CANULA TRAQUEOSTOMIA FENESTRADA CON BALON No 8.0 REF T-302-08 | I12: 006 | J12: Unidad | L12: 1 | M12: -33029.87 | N12: -33029.87
A13: 010 | B13: STOCK TERAPIA URGENCIAS | C13: 001 | D13: MEDICAMENTOS | E13: 29523-02 | F13: SODIO CLORURO 0.9% -50 ml Solución Inyectable | K13: 0.9% - 50 ml | L13: 1 | M13: -9389.8194 | N13: -9389.8194
A14: 010 | B14: STOCK TERAPIA URGENCIAS | C14: 002 | D14: MATERIAL MEDICO QUIRURGICO | E14: XT000015 | F14: FILTRO ANTIBACTERIANO NARIZ CAMELLO HYGROBAC ADULTO REF 63-804 | I14: 006 | J14: Unidad | L14: 1 | M14: -7674.6068 | N14: -7674.6068
A15: 020 | B15: STOCK FISIOTERAPIA UCI 2 | C15: 002 | D15: MATERIAL MEDICO QUIRURGICO | E15: XT000015 | F15: FILTRO ANTIBACTERIANO NARIZ CAMELLO HYGROBAC ADULTO REF 63-804 | I15: 006 | J15: Unidad | L15: 1 | M15: -7674.6068 | N15: -7674.6068
A16: 003 | B16: CARRO DE PARO RECUPERACION HEMODINAMIA | C16: 002 | D16: MATERIAL MEDICO QUIRURGICO | E16: XA000013 | F16: APOSITO TRANSPARENTE I.V ADVANCE 8.5 X 11.5 | I16: 006 | J16: Unidad | L16: 1 | M16: -1276.1739 | N16: -1276.1739
A17: 004 | B17: CARRO DE PARO RADIOLOGIA | C17: 002 | D17: MATERIAL MEDICO QUIRURGICO | E17: XA000013 | F17: APOSITO TRANSPARENTE I.V ADVANCE 8.5 X 11.5 | I17: 006 | J17: Unidad | L17: 1 | M17: -1276.1739 | N17: -1276.1739
A18: 014 | B18: CARRO DE PARO CARDIOLOGIA | C18: 002 | D18: MATERIAL MEDICO QUIRURGICO | E18: XA000013 | F18: APOSITO TRANSPARENTE I.V ADVANCE 8.5 X 11.5 | I18: 006 | J18: Unidad | L18: 1 | M18: -1276.1739 | N18: -1276.1739
A19: 015 | B19: CARRO DE PARO HEMODINAMIA | C19: 002 | D19: MATERIAL MEDICO QUIRURGICO | E19: XA000013 | F19: APOSITO TRANSPARENTE I.V ADVANCE 8.5 X 11.5 | I19: 006 | J19: Unidad | L19: 1 | M19: -1276.1739 | N19: -1276.1739
A20: 017 | B20: CARRO DE PARO UCI | C20: 002 | D20: MATERIAL MEDICO QUIRURGICO | E20: XA000013 | F20: APOSITO TRANSPARENTE I.V ADVANCE 8.5 X 11.5 | I20: 006 | J20: Unidad | L20: 1 | M20: -1276.1739 | N20: -1276.1739
A21: 022 | B21: CARRO DE PARO DE CIRUGIA | C21: 002 | D21: MATERIAL MEDICO QUIRURGICO | E21: XA000013 | F21: APOSITO TRANSPARENTE I.V ADVANCE 8.5 X 11.5 | I21: 006 | J21: Unidad | L21: 1 | M21: -1276.1739 | N21: -1276.1739
A22: 026 | B22: CARRO DE PARO TERCER PISO | C22: 002 | D22: MATERIAL MEDICO QUIRURGICO | E22: XA000013 | F22: APOSITO TRANSPARENTE I.V ADVANCE 8.5 X 11.5 | I22: 006 | J22: Unidad | L22: 1 | M22: -1276.1739 | N22: -1276.1739
A23: 029 | B23: CARRO DE PARO CUARTO PISO | C23: 002 | D23: MATERIAL MEDICO QUIRURGICO | E23: XA000013 | F23: APOSITO TRANSPARENTE I.V ADVANCE 8.5 X 11.5 | I23: 006 | J23: Unidad | L23: 1 | M23: -1276.1739 | N23: -1276.1739
A24: 057 | B24: CARRO DE PARO UCI 2 | C24: 002 | D24: MATERIAL MEDICO QUIRURGICO | E24: XA000013 | F24: APOSITO TRANSPARENTE I.V ADVANCE 8.5 X 11.5 | I24: 006 | J24: Unidad | L24: 1 | M24: -1276.1739 | N24: -1276.1739
A25: 009 | B25: CARRO DE PARO URGENCIAS | C25: 002 | D25: MATERIAL MEDICO QUIRURGICO | E25: XG000003 | F25: AGUJA DESECHABLE # 18 G.X1-1/2*100 | I25: 006 | J25: Unidad | L25: 1 | M25: 70.974908 | N25: 70.974908
A26: 001 | B26: FARMACIA CENTRAL | C26: 007 | D26: MEDICAMENTOS ANTIMICROBIANOS | E26: 19950177-01 | F26: DOXICICLINA 100 mg Tableta o Cápsula | K26: 100 mg | L26: 1 | M26: 214.08703 | N26: 214.08703
A27: 026 | B27: CARRO DE PARO TERCER PISO | C27: 002 | D27: MATERIAL MEDICO QUIRURGICO | E27: XJ000012 | F27: JERINGA DESECHABLE 3 ML-C/A-3 PARTES X100 | I27: 006 | J27: Unidad | L27: 1 | M27: 223.90058 | N27: 223.90058
A28: 026 | B28: CARRO DE PARO TERCER PISO | C28: 002 | D28: MATERIAL MEDICO QUIRURGICO | E28: XJ000015 | F28: JERINGA DESECHABLE DE INSULINA 1ML X 100UI. | I28: 006 | J28: Unidad | L28: 1 | M28: 229.47138 | N28: 229.47138
A29: 004 | B29: CARRO DE PARO RADIOLOGIA | C29: 002 | D29: MATERIAL MEDICO QUIRURGICO | E29: XG000028 | F29: HOJA BISTURI # 15 *100 | I29: 006 | J29: Unidad | L29: 1 | M29: 285.17608 | N29: 285.17608
A30: 009 | B30: CARRO DE PARO URGENCIAS | C30: 002 | D30: MATERIAL MEDICO QUIRURGICO | E30: XG000028 | F30: HOJA BISTURI # 15 *100 | I30: 006 | J30: Unidad | L30: 1 | M30: 285.17608 | N30: 285.17608
A31: 014 | B31: CARRO DE PARO CARDIOLOGIA | C31: 002 | D31: MATERIAL MEDICO QUIRURGICO | E31: XG000028 | F31: HOJA BISTURI # 15 *100 | I31: 006 | J31: Unidad | L31: 1 | M31: 285.17608 | N31: 285.17608
A32: 026 | B32: CARRO DE PARO TERCER PISO | C32: 002 | D32: MATERIAL MEDICO QUIRURGICO | E32: XG000028 | F32: HOJA BISTURI # 15 *100 | I32: 006 | J32: Unidad | L32: 1 | M32: 285.17608 | N32: 285.17608
A33: 018 | B33: STOCK FISIOTERAPIA UCI 1 | C33: 002 | D33: MATERIAL MEDICO QUIRURGICO | E33: XA000035 | F33: GASAS PAQUETE ESTERIL X5 | I33: 006 | J33: Unidad | L33: 1 | M33: 303.54017 | N33: 303.54017
A34: 059 | B34: BODEGA CUARENTENA | C34: 007 | D34: MEDICAMENTOS ANTIMICROBIANOS | E34: 19929856-13 | F34: CEFALEXINA 500 mg Cápsula | K34: 500 mg | L34: 1 | M34: 330.70025 | N34: 330.70025
A35: 001 | B35: FARMACIA CENTRAL | C35: 001 | D35: MEDICAMENTOS | E35: 201145-01 | F35: SULFASALAZINA 500 mg Tableta | K35: 500mg | L35: 1 | M35: 473.72246 | N35: 473.72246
A36: 022 | B36: CARRO DE PARO DE CIRUGIA | C36: 002 | D36: MATERIAL MEDICO QUIRURGICO | E36: XD000141 | F36: SONDA NELATON # 14 (UREATRAL)1 | I36: 006 | J36: Unidad | L36: 1 | M36: 574.28378 | N36: 574.28378
A37: 026 | B37: CARRO DE PARO TERCER PISO | C37: 002 | D37: MATERIAL MEDICO QUIRURGICO | E37: XD000141 | F37: SONDA NELATON # 14 (UREATRAL)1 | I37: 006 | J37: Unidad | L37: 1 | M37: 574.28378 | N37: 574.28378
A38: 001 | B38: FARMACIA CENTRAL | C38: 001 | D38: MEDICAMENTOS | E38: 19993923-15 | F38: METOCLOPRAMIDA 10 mg / 2 ml Solución Inyectable | K38: 10 mg / 2 ml | L38: 1 | M38: 592.115 | N38: 592.115
A39: 002 | B39: FARMACIA DE CIRUGIA | C39: 001 | D39: MEDICAMENTOS | E39: 19993923-15 | F39: METOCLOPRAMIDA 10 mg / 2 ml Solución Inyectable | K39: 10 mg / 2 ml | L39: 1 | M39: 592.115 | N39: 592.115
A40: 002 | B40: FARMACIA DE CIRUGIA | C40: 001 | D40: MEDICAMENTOS | E40: 19993036-08 | F40: DIPIRONA 1 g / 2 ml Solución inyectable | K40: 1 g | L40: 1 | M40: 612.47447 | N40: 612.47447
...

Sheet Dk Inventario
A3: Etiquetas de fila | B3: Grupo Nombre | C3: Suma de Costo Total
A4: 001 | B4: MEDICAMENTOS | C4: 1.2521984e+08 | D4: =+C4 -> 1.2521984e+08 | F4: =+D4+SUM(D7:D12)+D20 -> 3.2650138e+08
A5: 002 | B5: MATERIAL MEDICO QUIRURGICO | C5: 6.3247428e+08 | D5: =+C5 -> 6.3247428e+08 | F5: =+D5+D6 -> 6.3511349e+08
A6: 003 | B6: ELEMENTO DE CONSUMO | C6: 2639214.8 | D6: =+C6 -> 2639214.8
A7: 004 | B7: MEDICAMENTOS CONTROL ESPECIAL | C7: 15563453 | D7: =+C7 -> 15563453
A8: 005 | B8: MEDICAMENTOS ALTO COSTO | C8: 1.4960787e+08 | D8: =+C8 -> 1.4960787e+08
A9: 006 | B9: MEDICAMENTOS ANTICOAGULANTES | C9: 14335593 | D9: =+C9 -> 14335593
A10: 007 | B10: MEDICAMENTOS ANTIMICROBIANOS | C10: 9091094.6 | D10: =+C10 -> 9091094.6
A11: 008 | B11: MEDICAMENTOS ANTIRETROVIRALES | C11: 2260617.3 | D11: =+C11 -> 2260617.3
A12: 009 | B12: NUTRICIÓN | C12: 10422492 | D12: =+C12 -> 10422492
A13: 010 | B13: MATERIAL DE OSTEOSINTESIS | C13: 13479055 | D13: =+C13 -> 13479055
A14: 011 | B14: PAPELERIA Y ELEMENTOS DE OFICINA | C14: 29016829 | D14: =+C14 -> 29016829
A15: 012 | B15: MENAJE Y UTENSILIOS DE COCINA | C15: 1045119.2 | D15: =+C15 -> 1045119.2
A16: 013 | B16: DOTACION TRABAJADORES | C16: 21244080 | D16: =+C16 -> 21244080
A17: 014 | B17: ROPERIA | C17: 20882765 | D17: =+C17 -> 20882765
... A20: 017 | B20: MEDICAMENTOS SALUD PUBLICA | C20: 413 | D20: =+C20 -> 413
A21: Total general | C21: 1.2316113e+09 | D21: =SUM(D4:D20) -> 1.2316113e+09

Sheet Conciliacion
B2: Concepto | C2: Saldo Contab | D2: Saldo Inventarios | E2: Diferencia
B3: DOTACION TRABAJADORES | C3: =+Bg!K149 -> 20913018 | D3: =+'Dk Inventario'!D16 -> 21244080 | E3: =+C3-D3 -> -331062.07
B4: ELEMENTOS DE ASEO | C4: =+Bg!K150 -> 37945852 | D4: =+'Dk Inventario'!D19 -> 41291435 | E4: =+C4-D4 -> -3345583.2
B5: MATERIAL DE OSTEOSINTESIS | C5: =+Bg!K144 -> 13402082 | D5: =+'Dk Inventario'!D13 -> 13479055 | E5: =+C5-D5 -> -76973.66
B6: MATERIALES Y REPUESTOS | C6: =+Bg!K152 -> 1.5406274e+08 | D6: =+'Dk Inventario'!D18 -> 1.4303718e+08 | E6: =+C6-D6 -> 11025564
B7: MEDICAMENTOS | C7: =+Bg!K139 -> 3.2673695e+08 | D7: =+'Dk Inventario'!F4 -> 3.2650138e+08 | E7: =+C7-D7 -> 235576.64
B8: MEDICO QUIRURGICOS | C8: =+Bg!K143 -> 6.8282496e+08 | D8: =+'Dk Inventario'!F5 -> 6.3511349e+08 | E8: =+C8-D8 -> 47711467
B9: MENAJE Y UTENSILIOS DE COCINA | C9: =+Bg!K153 -> 1333208.8 | D9: =+'Dk Inventario'!D15 -> 1045119.2 | E9: =+C9-D9 -> 288089.64
B10: PAPELERIA Y ELEMENTOS DE OFICINA | C10: =+Bg!K151 -> 24181685 | D10: =+'Dk Inventario'!D14 -> 29016829 | E10: =+C10-D10 -> -4835144.2
B11: ROPERIA | C11: =+Bg!K148 -> 19769422 | D11: =+'Dk Inventario'!D17 -> 20882765 | E11: =+C11-D11 -> -1113343
B12: TOTAL | C12: =SUM(C3:C11) -> 1.2811699e+09 | D12: =SUM(D3:D11) -> 1.2316113e+09 | E12: =SUM(E3:E11) -> 49558591
C14: =+C12-Bg!K135 -> 0 | D14: =+D12-GETPIVOTDATA("Costo Total",'Dk Inventario'!$A$3) -> 0
